Workbook

Sheet Workbook Master
A1: PROPERTY | B1: QTY | C1: AMOUNT | D1: Cash Received | E1: PA Rev Share | F1: Transition Date | G1: Notes
A2: 48 West - Rent Plus Services | B2: =SUMIFS('Count Workbook (sans para.)'!B:B,'Count Workbook (sans para.)'!A:A,$A2) -> 579 | C2: =SUMIFS('Count Workbook (sans para.)'!D:D,'Count Workbook (sans para.)'!A:A,$A2) -> 4545.15 | D2: =_xlfn.XLOOKUP($J2,ChargeCode[Property],ChargeCode[Total Cash Collections],"error") -> 5630 | E2: =Table53[[#This Row],[Cash Received]]-Table53[[#This Row],[AMOUNT]] -> 1084.85 | I2: =Table53[[#This Row],[PROPERTY]] -> 48 West - Rent Plus Services | J2: 48 West
A3: 555 Boulevard - Rent Plus Services | B3: =SUMIFS('Count Workbook (sans para.)'!B:B,'Count Workbook (sans para.)'!A:A,$A3) -> 53 | C3: =SUMIFS('Count Workbook (sans para.)'!D:D,'Count Workbook (sans para.)'!A:A,$A3) -> 432.45 | D3: =_xlfn.XLOOKUP($J3,ChargeCode[Property],ChargeCode[Total Cash Collections],"error") -> 502.92 | E3: =Table53[[#This Row],[Cash Received]]-Table53[[#This Row],[AMOUNT]] -> 70.47 | I3: =Table53[[#This Row],[PROPERTY]] -> 555 Boulevard - Rent Plus Services | J3: 555 Boulevard
A4: 698 Prospect - Rent Plus Services | B4: =SUMIFS('Count Workbook (sans para.)'!B:B,'Count Workbook (sans para.)'!A:A,$A4) -> 118 | C4: =SUMIFS('Count Workbook (sans para.)'!D:D,'Count Workbook (sans para.)'!A:A,$A4) -> 926.3 | D4: =_xlfn.XLOOKUP($J4,ChargeCode[Property],ChargeCode[Total Cash Collections],"error") -> 1075.94 | E4: =Table53[[#This Row],[Cash Received]]-Table53[[#This Row],[AMOUNT]] -> 149.64 | I4: =Table53[[#This Row],[PROPERTY]] -> 698 Prospect - Rent Plus Services | J4: 698 Prospect
A5: Auden Upstate - Rent Plus Services | B5: =SUMIFS('Count Workbook (sans para.)'!B:B,'Count Workbook (sans para.)'!A:A,$A5) -> 37 | C5: =SUMIFS('Count Workbook (sans para.)'!D:D,'Count Workbook (sans para.)'!A:A,$A5) -> 290.45 | D5: =_xlfn.XLOOKUP($J5,ChargeCode[Property],ChargeCode[Total Cash Collections],"error") -> 340 | E5: =Table53[[#This Row],[Cash Received]]-Table53[[#This Row],[AMOUNT]] -> 49.55 | I5: =Table53[[#This Row],[PROPERTY]] -> Auden Upstate - Rent Plus Services | J5: Auden Upstate
A6: Beach Club - Rent Plus Services | B6: =SUMIFS('Count Workbook (sans para.)'!B:B,'Count Workbook (sans para.)'!A:A,$A6) -> 133 | C6: =SUMIFS('Count Workbook (sans para.)'!D:D,'Count Workbook (sans para.)'!A:A,$A6) -> 1058.65 | D6: =_xlfn.XLOOKUP($J6,ChargeCode[Property],ChargeCode[Total Cash Collections],"error") -> 817.72 | E6: =Table53[[#This Row],[Cash Received]]-Table53[[#This Row],[AMOUNT]] -> -240.93 | I6: =Table53[[#This Row],[PROPERTY]] -> Beach Club - Rent Plus Services | J6: Beach Club
A7: Bixby Kennesaw - Rent Plus Services | B7: =SUMIFS('Count Workbook (sans para.)'!B:B,'Count Workbook (sans para.)'!A:A,$A7) -> 369 | C7: =SUMIFS('Count Workbook (sans para.)'!D:D,'Count Workbook (sans para.)'!A:A,$A7) -> 2896.65 | D7: =_xlfn.XLOOKUP($J7,ChargeCode[Property],ChargeCode[Total Cash Collections],"error") -> 3530 | E7: =Table53[[#This Row],[Cash Received]]-Table53[[#This Row],[AMOUNT]] -> 633.35 | I7: =Table53[[#This Row],[PROPERTY]] -> Bixby Kennesaw - Rent Plus Services | J7: Bixby Kennesaw
A8: Brooks at Stillwater - Rent Plus Services | B8: =SUMIFS('Count Workbook (sans para.)'!B:B,'Count Workbook (sans para.)'!A:A,$A8) -> 375 | C8: =SUMIFS('Count Workbook (sans para.)'!D:D,'Count Workbook (sans para.)'!A:A,$A8) -> 2301.75 | D8: =_xlfn.XLOOKUP($J8,ChargeCode[Property],ChargeCode[Total Cash Collections],"error") -> 3389 | E8: =Table53[[#This Row],[Cash Received]]-Table53[[#This Row],[AMOUNT]] -> 1087.25 | I8: =Table53[[#This Row],[PROPERTY]] -> Brooks at Stillwater - Rent Plus Services | J8: Brooks at Stillwater
A9: Campus Creek Cottages - Rent Plus Services | B9: =SUMIFS('Count Workbook (sans para.)'!B:B,'Count Workbook (sans para.)'!A:A,$A9) -> 164 | C9: =SUMIFS('Count Workbook (sans para.)'!D:D,'Count Workbook (sans para.)'!A:A,$A9) -> 1283.4 | D9: =_xlfn.XLOOKUP($J9,ChargeCode[Property],ChargeCode[Total Cash Collections],"error") -> 1537 | E9: =Table53[[#This Row],[Cash Received]]-Table53[[#This Row],[AMOUNT]] -> 253.6 | I9: =Table53[[#This Row],[PROPERTY]] -> Campus Creek Cottages - Rent Plus Services | J9: Campus Creek Cottages
A10: Campus Creek Townhomes - Rent Plus Services | B10: =SUMIFS('Count Workbook (sans para.)'!B:B,'Count Workbook (sans para.)'!A:A,$A10) -> 101 | C10: =SUMIFS('Count Workbook (sans para.)'!D:D,'Count Workbook (sans para.)'!A:A,$A10) -> 789.85 | D10: =_xlfn.XLOOKUP($J10,ChargeCode[Property],ChargeCode[Total Cash Collections],"error") -> 937 | E10: =Table53[[#This Row],[Cash Received]]-Table53[[#This Row],[AMOUNT]] -> 147.15 | I10: =Table53[[#This Row],[PROPERTY]] -> Campus Creek Townhomes - Rent Plus Services | J10: Campus Creek Townhomes
A11: Castleberry Park - Rent Plus Services | B11: =SUMIFS('Count Workbook (sans para.)'!B:B,'Count Workbook (sans para.)'!A:A,$A11) -> 46 | C11: =SUMIFS('Count Workbook (sans para.)'!D:D,'Count Workbook (sans para.)'!A:A,$A11) -> 376.8 | D11: =_xlfn.XLOOKUP($J11,ChargeCode[Property],ChargeCode[Total Cash Collections],"error") -> 423.95 | E11: =Table53[[#This Row],[Cash Received]]-Table53[[#This Row],[AMOUNT]] -> 47.15 | I11: =Table53[[#This Row],[PROPERTY]] -> Castleberry Park - Rent Plus Services | J11: Castleberry Park
A12: Chateau on Wells - Rent Plus Services | B12: =SUMIFS('Count Workbook (sans para.)'!B:B,'Count Workbook (sans para.)'!A:A,$A12) -> 4 | C12: =SUMIFS('Count Workbook (sans para.)'!D:D,'Count Workbook (sans para.)'!A:A,$A12) -> 31.4 | D12: =_xlfn.XLOOKUP($J12,ChargeCode[Property],ChargeCode[Total Cash Collections],"error") -> 40 | E12: =Table53[[#This Row],[Cash Received]]-Table53[[#This Row],[AMOUNT]] -> 8.6 | I12: =Table53[[#This Row],[PROPERTY]] -> Chateau on Wells - Rent Plus Services | J12: Chateau on Wells
A13: Clemson Edge - Rent Plus Services | B13: =SUMIFS('Count Workbook (sans para.)'!B:B,'Count Workbook (sans para.)'!A:A,$A13) -> 232 | C13: =SUMIFS('Count Workbook (sans para.)'!D:D,'Count Workbook (sans para.)'!A:A,$A13) -> 1821.2 | D13: =_xlfn.XLOOKUP($J13,ChargeCode[Property],ChargeCode[Total Cash Collections],"error") -> 2320 | E13: =Table53[[#This Row],[Cash Received]]-Table53[[#This Row],[AMOUNT]] -> 498.8 | I13: =Table53[[#This Row],[PROPERTY]] -> Clemson Edge - Rent Plus Services | J13: Clemson Edge
... A65: Villas on Rio - Rent Plus Services | B65: =SUMIFS('Count Workbook (sans para.)'!B:B,'Count Workbook (sans para.)'!A:A,$A65) -> 506 | C65: =SUMIFS('Count Workbook (sans para.)'!D:D,'Count Workbook (sans para.)'!A:A,$A65) -> 3972.1 | D65: =_xlfn.XLOOKUP($J65,ChargeCode[Property],ChargeCode[Total Cash Collections],"error") -> 5050 | E65: =Table53[[#This Row],[Cash Received]]-Table53[[#This Row],[AMOUNT]] -> 1077.9 | I65: =Table53[[#This Row],[PROPERTY]] -> Villas on Rio - Rent Plus Services | J65: Villas on Rio
B66: =SUBTOTAL(109,Table53[QTY]) -> 14260 | C66: =SUBTOTAL(109,Table53[AMOUNT]) -> 109790.25 | D66: =SUBTOTAL(109,Table53[Cash Received]) -> 139374.66 | E66: =SUBTOTAL(109,Table53[PA Rev Share]) -> 29584.41
A69: Notes
A70: total policies charged by RentPlus = | B70: =Table53[[#Totals],[QTY]] -> 14260
A71: Peak revenue share from Rent+ @ $2.24/bed | C71: =B70*2.24 -> 31942.4 | D71: 31152
A73: Invoice from Rent+ | C73: =Table53[[#Totals],[AMOUNT]] -> 109790.25
A74: Property rev share | C74: =Table53[[#Totals],[PA Rev Share]] -> 29584.41
A75: Total collected | C75: =SUM(C73:C74) -> 139374.66
B76: s/b zero | C76: =C75-Table53[[#Totals],[Cash Received]] -> 0
A78: Note: Corporate ACCT pulls the "amounts " in Column C from each property to pay the Rent+ invoice.

Sheet Receipts By Charge Codes - RP (
A1: Property | B1: Charge Code | C1: GL Account | D1: Total Charges | E1: Prior Collections | F1: Current Collections | G1: Total Cash Collections | H1: Credits / Concessions | I1: Total Collections
A2: 48 West | B2: RentPlus | C2: 2010-40: RentPlus Payable | D2: 5850 | E2: 780 | F2: 4850 | G2: 5630 | H2: 20 | I2: 5713
A3: 555 Boulevard | B3: RentPlus | C3: 2010-40: RentPlus Payable | D3: 536.45 | E3: 53.53 | F3: 449.39 | G3: 502.92 | H3: 0 | I3: 1090
A4: 698 Prospect | B4: RentPlus | C4: 2010-40: RentPlus Payable | D4: 1140 | E4: 287 | F4: 788.94 | G4: 1075.94 | H4: 0 | I4: 310
A5: Auden Upstate | B5: RentPlus | C5: 2010-40: RentPlus Payable | D5: 370 | E5: 50 | F5: 290 | G5: 340 | H5: 261.8 | I5: 1165.05
A6: Beach Club | B6: RentPlus | C6: 2010-40: RentPlus Payable | D6: 1101.85 | E6: 140.55 | F6: 677.17 | G6: 817.72 | H6: -20 | I6: 3643
A7: Bixby Kennesaw | B7: RentPlus | C7: 2010-40: RentPlus Payable | D7: 3680 | E7: 520 | F7: 3010 | G7: 3530 | H7: 0 | I7: 3324.82
A8: Brooks at Stillwater | B8: RentPlus | C8: 2010-40: RentPlus Payable | D8: 3339 | E8: 144.25 | F8: 3244.75 | G8: 3389 | H8: -29 | I8: 1557
A9: Campus Creek Cottages | B9: RentPlus | C9: 2010-40: RentPlus Payable | D9: 1586 | E9: 170 | F9: 1367 | G9: 1537 | H9: 9 | I9: 956
A10: Campus Creek Townhomes | B10: RentPlus | C10: 2010-40: RentPlus Payable | D10: 1015 | E10: 119 | F10: 818 | G10: 937 | H10: 0 | I10: 30
A11: Castleberry Park | B11: RentPlus | C11: 2010-40: RentPlus Payable | D11: 475.7 | E11: 93.56 | F11: 330.39 | G11: 423.95 | H11: 0 | I11: 45.6
A12: Chateau on Wells | B12: RentPlus | C12: 2010-40: RentPlus Payable | D12: 40 | E12: 0 | F12: 40 | G12: 40 | H12: 20 | I12: 2310
A13: Claremont Collegiate Apartments | B13: RentPlus | C13: 2010-40: RentPlus Payable | D13: 51.3 | E13: 0 | F13: 34.2 | G13: 34.2 | H13: 40 | I13: 5780
... A69: University Edge Akron | B69: RentPlus | C69: 2010-40: RentPlus Payable | D69: 249 | E69: 70 | F69: 177 | G69: 247 | H69: 10 | I69: 5070
A70: University Gateway | B70: RentPlus | C70: 2010-40: RentPlus Payable | D70: 2787.3 | E70: 347.7 | F70: 2388.3 | G70: 2736
A71: Uno on Chestnut | B71: RentPlus | C71: 2010-40: RentPlus Payable | D71: 740 | E71: 30 | F71: 690 | G71: 720
A72: Valley Falls Apartments | B72: RentPlus | C72: 2010-40: RentPlus Payable | D72: 3870 | E72: 540 | F72: 3290 | G72: 3830
A73: Villas on Rio | B73: RentPlus | C73: 2010-40: RentPlus Payable | D73: 5060 | E73: 230 | F73: 4820 | G73: 5050

Sheet Count Workbook (sans para.)
A1: PROPERTY | B1: QTY | C1: UNIT PRICE | D1: AMOUNT
A2: 48 West - Rent Plus Services | B2: 579 | C2: 7.85 | D2: 4545.15
A3: 555 Boulevard - Rent Plus Services | B3: 36 | C3: 6.8 | D3: 244.8
A4: 555 Boulevard - Rent Plus Services | B4: 5 | C4: 7.8 | D4: 39
A5: 555 Boulevard - Rent Plus Services | B5: 1 | C5: 7.85 | D5: 7.85
A6: 555 Boulevard - Rent Plus Services | B6: 11 | C6: 12.8 | D6: 140.8
A7: 698 Prospect - Rent Plus Services | B7: 118 | C7: 7.85 | D7: 926.3
A8: Auden Upstate - Rent Plus Services | B8: 37 | C8: 7.85 | D8: 290.45
A9: Beach Club - Rent Plus Services | B9: 67 | C9: 6.8 | D9: 455.6
A10: Beach Club - Rent Plus Services | B10: 55 | C10: 7.85 | D10: 431.75
A11: Beach Club - Rent Plus Services | B11: 1 | C11: 12.8 | D11: 12.8
A12: Beach Club - Rent Plus Services | B12: 8 | C12: 14.65 | D12: 117.2
A13: Beach Club - Rent Plus Services | B13: 2 | C13: 20.65 | D13: 41.3
... A91: Villas on Rio - Rent Plus Services | B91: 506 | C91: 7.85 | D91: 3972.1
B92: =SUBTOTAL(109,Table54[QTY]) -> 14260 | C92: =SUBTOTAL(109,Table54[UNIT PRICE]) -> 735.35 | D92: =SUBTOTAL(109,Table54[AMOUNT]) -> 109790.25

Sheet Count Workbook (Formulas)
A1: PROPERTY | B1: QTY | C1: UNIT PRICE | D1: AMOUNT
A2: 48 West - Rent Plus Services | B2: =SUMIFS('Invoice Data'!G:G,'Invoice Data'!B:B,$A2) -> 579 | C2: 7.85 | D2: =$B2*$C2 -> 4545.15
A3: 555 Boulevard - Rent Plus Services (past) | B3: =SUMIFS('Invoice Data'!G:G,'Invoice Data'!B:B,$A3) -> 36 | C3: 6.8 | D3: =$B3*$C3 -> 244.8
A4: 555 Boulevard - Rent Plus Services (past double) | B4: =SUMIFS('Invoice Data'!G:G,'Invoice Data'!B:B,$A4) -> 5 | C4: 7.8 | D4: =$B4*$C4 -> 39
A5: 555 Boulevard - Rent Plus Services | B5: =SUMIFS('Invoice Data'!G:G,'Invoice Data'!B:B,$A5) -> 1 | C5: 7.85 | D5: =$B5*$C5 -> 7.85
A6: 555 Boulevard - Rent Plus Services (past triple) | B6: =SUMIFS('Invoice Data'!G:G,'Invoice Data'!B:B,$A6) -> 11 | C6: 12.8 | D6: =$B6*$C6 -> 140.8
A7: 698 Prospect - Rent Plus Services | B7: =SUMIFS('Invoice Data'!G:G,'Invoice Data'!B:B,$A7) -> 118 | C7: 7.85 | D7: =$B7*$C7 -> 926.3
A8: Auden Upstate - Rent Plus Services | B8: =SUMIFS('Invoice Data'!G:G,'Invoice Data'!B:B,$A8) -> 37 | C8: 7.85 | D8: =$B8*$C8 -> 290.45
A9: Beach Club - Rent Plus Services (past) | B9: =SUMIFS('Invoice Data'!G:G,'Invoice Data'!B:B,$A9) -> 67 | C9: 6.8 | D9: =$B9*$C9 -> 455.6
A10: Beach Club - Rent Plus Services | B10: =SUMIFS('Invoice Data'!G:G,'Invoice Data'!B:B,$A10) -> 55 | C10: 7.85 | D10: =$B10*$C10 -> 431.75
A11: Beach Club - Rent Plus Services (past double) | B11: =SUMIFS('Invoice Data'!G:G,'Invoice Data'!B:B,$A11) -> 1 | C11: 12.8 | D11: =$B11*$C11 -> 12.8
A12: Beach Club - Rent Plus Services (past triple) | B12: =SUMIFS('Invoice Data'!G:G,'Invoice Data'!B:B,$A12) -> 8 | C12: 14.65 | D12: =$B12*$C12 -> 117.2
A13: Beach Club - Rent Plus Services (past quad) | B13: =SUMIFS('Invoice Data'!G:G,'Invoice Data'!B:B,$A13) -> 2 | C13: 20.65 | D13: =$B13*$C13 -> 41.3
... A91: Villas on Rio - Rent Plus Services | B91: =SUMIFS('Invoice Data'!G:G,'Invoice Data'!B:B,$A91) -> 506 | C91: 7.85 | D91: =$B91*$C91 -> 3972.1
B92: =SUBTOTAL(109,Table5[QTY]) -> 14260 | C92: =SUBTOTAL(109,Table5[UNIT PRICE]) -> 735.35 | D92: =SUBTOTAL(109,Table5[AMOUNT]) -> 109790.25

Sheet Invoice Data
A1: ITEM # | B1: DESCRIPTION | C1: UNIT | D1: QTY | E1: UNIT PRICE | F1: AMOUNT | G1: Count (DO NOT DELETE THIS COLUMN | H1: Reversals (DO NOT DELETE) | M1: GUIDE FOR WORKBOOK | N1: Column1 | O1: Rate | P1: Multiplier
A2: 1020 | B2: 48 West - Rent Plus Services | C2: Each | D2: 573 | E2: 7.85 | F2: 4498.05 | G2: {=SUMPRODUCT(IF($E2=$O$2,$D2*$P$2,IF($E2=$O$3,$D2*$P$3,IF($E2=$O$4,$D2*$P$4,IF($E2=$O$5,$D2*$P$5,IF($E2=$O$6,$D2*$P$6, IF($E2=$O$7,$D2*$P$7,IF($E2=$O$8,$D2*$P$8,IF($E2=$O$9,$D2*$P$9,IF($E2=$O$10,$D2*$P$10,IF($E2=$O$11,$D2*$P$11,IF($E2=$O$12,$D2*$P$12,IF($E2=$O$13,$D2*$P$13,IF($E2=$O$14,$D2*$P$14,IF($E2=$O$15,$D2*$P$15,IF($E2=$O$16,$D2*$P$16,IF($E2=$O$17,$D2*$P$17,IF($E2=$O$18,$D2*$P$18,IF($E2=$O$19,$D2*$P$19,IF($E2=$O$20,$D2*$P$20,IF($E2=$O$21,$D2*$P$21,IF($E2=$O$22,$D2*$P$22,IF($E2=$O$23,$D2*$P$23,IF($E2=$O$24,$D2*$P$24,IF($E2=$O$25,$D2*$P$25,IF($E2=$O$26,$D2*$P$26,IF($E2=$O$27,$D2*$P$27,IF($E2=$O$28,$D2*$P$28,IF($E2=$O$29,$D2*$P$29,IF($E2=$O$30,$D2*$P$30,IF($E2=$O$31,$D2*$P$31,IF($E2=$O$32,$D2*$P$32,IF($E2=$O$33,$D2*$P$33,IF($E2=$O$34,$D2*$P$34,IF($E2=$O$35,$D2*$P$35,n/a)))))))))))))))))))))))))))))))))))} -> 573 | H2: =IF($E2<0,$G2*10,0) -> 0 | M2: Peak | N2: Single Charge | O2: 7.85 | P2: 1
A3: 1020 | B3: 48 West - Rent Plus Services | C3: Each | D3: 4 | E3: 15.7 | F3: 62.8 | G3: {=SUMPRODUCT(IF($E3=$O$2,$D3*$P$2,IF($E3=$O$3,$D3*$P$3,IF($E3=$O$4,$D3*$P$4,IF($E3=$O$5,$D3*$P$5,IF($E3=$O$6,$D3*$P$6, IF($E3=$O$7,$D3*$P$7,IF($E3=$O$8,$D3*$P$8,IF($E3=$O$9,$D3*$P$9,IF($E3=$O$10,$D3*$P$10,IF($E3=$O$11,$D3*$P$11,IF($E3=$O$12,$D3*$P$12,IF($E3=$O$13,$D3*$P$13,IF($E3=$O$14,$D3*$P$14,IF($E3=$O$15,$D3*$P$15,IF($E3=$O$16,$D3*$P$16,IF($E3=$O$17,$D3*$P$17,IF($E3=$O$18,$D3*$P$18,IF($E3=$O$19,$D3*$P$19,IF($E3=$O$20,$D3*$P$20,IF($E3=$O$21,$D3*$P$21,IF($E3=$O$22,$D3*$P$22,IF($E3=$O$23,$D3*$P$23,IF($E3=$O$24,$D3*$P$24,IF($E3=$O$25,$D3*$P$25,IF($E3=$O$26,$D3*$P$26,IF($E3=$O$27,$D3*$P$27,IF($E3=$O$28,$D3*$P$28,IF($E3=$O$29,$D3*$P$29,IF($E3=$O$30,$D3*$P$30,IF($E3=$O$31,$D3*$P$31,IF($E3=$O$32,$D3*$P$32,IF($E3=$O$33,$D3*$P$33,IF($E3=$O$34,$D3*$P$34,IF($E3=$O$35,$D3*$P$35,n/a)))))))))))))))))))))))))))))))))))} -> 8 | H3: =IF($E3<0,$G3*10,0) -> 0 | N3: Double Charge | O3: 15.7 | P3: 2
A4: 1020 | B4: 48 West - Rent Plus Services | C4: Each | D4: 1 | E4: 31.4 | F4: 31.4 | G4: {=SUMPRODUCT(IF($E4=$O$2,$D4*$P$2,IF($E4=$O$3,$D4*$P$3,IF($E4=$O$4,$D4*$P$4,IF($E4=$O$5,$D4*$P$5,IF($E4=$O$6,$D4*$P$6, IF($E4=$O$7,$D4*$P$7,IF($E4=$O$8,$D4*$P$8,IF($E4=$O$9,$D4*$P$9,IF($E4=$O$10,$D4*$P$10,IF($E4=$O$11,$D4*$P$11,IF($E4=$O$12,$D4*$P$12,IF($E4=$O$13,$D4*$P$13,IF($E4=$O$14,$D4*$P$14,IF($E4=$O$15,$D4*$P$15,IF($E4=$O$16,$D4*$P$16,IF($E4=$O$17,$D4*$P$17,IF($E4=$O$18,$D4*$P$18,IF($E4=$O$19,$D4*$P$19,IF($E4=$O$20,$D4*$P$20,IF($E4=$O$21,$D4*$P$21,IF($E4=$O$22,$D4*$P$22,IF($E4=$O$23,$D4*$P$23,IF($E4=$O$24,$D4*$P$24,IF($E4=$O$25,$D4*$P$25,IF($E4=$O$26,$D4*$P$26,IF($E4=$O$27,$D4*$P$27,IF($E4=$O$28,$D4*$P$28,IF($E4=$O$29,$D4*$P$29,IF($E4=$O$30,$D4*$P$30,IF($E4=$O$31,$D4*$P$31,IF($E4=$O$32,$D4*$P$32,IF($E4=$O$33,$D4*$P$33,IF($E4=$O$34,$D4*$P$34,IF($E4=$O$35,$D4*$P$35,n/a)))))))))))))))))))))))))))))))))))} -> 4 | H4: =IF($E4<0,$G4*10,0) -> 0 | N4: Triple Charge | O4: 23.55 | P4: 3
A5: 1020 | B5: 48 West - Rent Plus Services | C5: Each | D5: 4 | E5: -7.85 | F5: -31.4 | G5: {=SUMPRODUCT(IF($E5=$O$2,$D5*$P$2,IF($E5=$O$3,$D5*$P$3,IF($E5=$O$4,$D5*$P$4,IF($E5=$O$5,$D5*$P$5,IF($E5=$O$6,$D5*$P$6, IF($E5=$O$7,$D5*$P$7,IF($E5=$O$8,$D5*$P$8,IF($E5=$O$9,$D5*$P$9,IF($E5=$O$10,$D5*$P$10,IF($E5=$O$11,$D5*$P$11,IF($E5=$O$12,$D5*$P$12,IF($E5=$O$13,$D5*$P$13,IF($E5=$O$14,$D5*$P$14,IF($E5=$O$15,$D5*$P$15,IF($E5=$O$16,$D5*$P$16,IF($E5=$O$17,$D5*$P$17,IF($E5=$O$18,$D5*$P$18,IF($E5=$O$19,$D5*$P$19,IF($E5=$O$20,$D5*$P$20,IF($E5=$O$21,$D5*$P$21,IF($E5=$O$22,$D5*$P$22,IF($E5=$O$23,$D5*$P$23,IF($E5=$O$24,$D5*$P$24,IF($E5=$O$25,$D5*$P$25,IF($E5=$O$26,$D5*$P$26,IF($E5=$O$27,$D5*$P$27,IF($E5=$O$28,$D5*$P$28,IF($E5=$O$29,$D5*$P$29,IF($E5=$O$30,$D5*$P$30,IF($E5=$O$31,$D5*$P$31,IF($E5=$O$32,$D5*$P$32,IF($E5=$O$33,$D5*$P$33,IF($E5=$O$34,$D5*$P$34,IF($E5=$O$35,$D5*$P$35,n/a)))))))))))))))))))))))))))))))))))} -> -4 | H5: =IF($E5<0,$G5*10,0) -> -40 | N5: Quad Charge | O5: 31.4 | P5: 4
A6: 1020 | B6: 48 West - Rent Plus Services | C6: Each | D6: 1 | E6: -15.7 | F6: -15.7 | G6: {=SUMPRODUCT(IF($E6=$O$2,$D6*$P$2,IF($E6=$O$3,$D6*$P$3,IF($E6=$O$4,$D6*$P$4,IF($E6=$O$5,$D6*$P$5,IF($E6=$O$6,$D6*$P$6, IF($E6=$O$7,$D6*$P$7,IF($E6=$O$8,$D6*$P$8,IF($E6=$O$9,$D6*$P$9,IF($E6=$O$10,$D6*$P$10,IF($E6=$O$11,$D6*$P$11,IF($E6=$O$12,$D6*$P$12,IF($E6=$O$13,$D6*$P$13,IF($E6=$O$14,$D6*$P$14,IF($E6=$O$15,$D6*$P$15,IF($E6=$O$16,$D6*$P$16,IF($E6=$O$17,$D6*$P$17,IF($E6=$O$18,$D6*$P$18,IF($E6=$O$19,$D6*$P$19,IF($E6=$O$20,$D6*$P$20,IF($E6=$O$21,$D6*$P$21,IF($E6=$O$22,$D6*$P$22,IF($E6=$O$23,$D6*$P$23,IF($E6=$O$24,$D6*$P$24,IF($E6=$O$25,$D6*$P$25,IF($E6=$O$26,$D6*$P$26,IF($E6=$O$27,$D6*$P$27,IF($E6=$O$28,$D6*$P$28,IF($E6=$O$29,$D6*$P$29,IF($E6=$O$30,$D6*$P$30,IF($E6=$O$31,$D6*$P$31,IF($E6=$O$32,$D6*$P$32,IF($E6=$O$33,$D6*$P$33,IF($E6=$O$34,$D6*$P$34,IF($E6=$O$35,$D6*$P$35,n/a)))))))))))))))))))))))))))))))))))} -> -2 | H6: =IF($E6<0,$G6*10,0) -> -20 | N6: Reversal | O6: -7.85 | P6: -1
A7: 1020 | B7: 555 Boulevard - Rent Plus Services (past) | C7: Each | D7: 36 | E7: 6.8 | F7: 244.8 | G7: {=SUMPRODUCT(IF($E7=$O$2,$D7*$P$2,IF($E7=$O$3,$D7*$P$3,IF($E7=$O$4,$D7*$P$4,IF($E7=$O$5,$D7*$P$5,IF($E7=$O$6,$D7*$P$6, IF($E7=$O$7,$D7*$P$7,IF($E7=$O$8,$D7*$P$8,IF($E7=$O$9,$D7*$P$9,IF($E7=$O$10,$D7*$P$10,IF($E7=$O$11,$D7*$P$11,IF($E7=$O$12,$D7*$P$12,IF($E7=$O$13,$D7*$P$13,IF($E7=$O$14,$D7*$P$14,IF($E7=$O$15,$D7*$P$15,IF($E7=$O$16,$D7*$P$16,IF($E7=$O$17,$D7*$P$17,IF($E7=$O$18,$D7*$P$18,IF($E7=$O$19,$D7*$P$19,IF($E7=$O$20,$D7*$P$20,IF($E7=$O$21,$D7*$P$21,IF($E7=$O$22,$D7*$P$22,IF($E7=$O$23,$D7*$P$23,IF($E7=$O$24,$D7*$P$24,IF($E7=$O$25,$D7*$P$25,IF($E7=$O$26,$D7*$P$26,IF($E7=$O$27,$D7*$P$27,IF($E7=$O$28,$D7*$P$28,IF($E7=$O$29,$D7*$P$29,IF($E7=$O$30,$D7*$P$30,IF($E7=$O$31,$D7*$P$31,IF($E7=$O$32,$D7*$P$32,IF($E7=$O$33,$D7*$P$33,IF($E7=$O$34,$D7*$P$34,IF($E7=$O$35,$D7*$P$35,n/a)))))))))))))))))))))))))))))))))))} -> 36 | H7: =IF($E7<0,$G7*10,0) -> 0 | N7: Reversal | O7: -15.7 | P7: -2
A8: 1020 | B8: 555 Boulevard - Rent Plus Services (past double) | C8: Each | D8: 6 | E8: 7.8 | F8: 46.8 | G8: {=SUMPRODUCT(IF($E8=$O$2,$D8*$P$2,IF($E8=$O$3,$D8*$P$3,IF($E8=$O$4,$D8*$P$4,IF($E8=$O$5,$D8*$P$5,IF($E8=$O$6,$D8*$P$6, IF($E8=$O$7,$D8*$P$7,IF($E8=$O$8,$D8*$P$8,IF($E8=$O$9,$D8*$P$9,IF($E8=$O$10,$D8*$P$10,IF($E8=$O$11,$D8*$P$11,IF($E8=$O$12,$D8*$P$12,IF($E8=$O$13,$D8*$P$13,IF($E8=$O$14,$D8*$P$14,IF($E8=$O$15,$D8*$P$15,IF($E8=$O$16,$D8*$P$16,IF($E8=$O$17,$D8*$P$17,IF($E8=$O$18,$D8*$P$18,IF($E8=$O$19,$D8*$P$19,IF($E8=$O$20,$D8*$P$20,IF($E8=$O$21,$D8*$P$21,IF($E8=$O$22,$D8*$P$22,IF($E8=$O$23,$D8*$P$23,IF($E8=$O$24,$D8*$P$24,IF($E8=$O$25,$D8*$P$25,IF($E8=$O$26,$D8*$P$26,IF($E8=$O$27,$D8*$P$27,IF($E8=$O$28,$D8*$P$28,IF($E8=$O$29,$D8*$P$29,IF($E8=$O$30,$D8*$P$30,IF($E8=$O$31,$D8*$P$31,IF($E8=$O$32,$D8*$P$32,IF($E8=$O$33,$D8*$P$33,IF($E8=$O$34,$D8*$P$34,IF($E8=$O$35,$D8*$P$35,n/a)))))))))))))))))))))))))))))))))))} -> 6 | H8: =IF($E8<0,$G8*10,0) -> 0 | N8: Reversal | O8: -23.55 | P8: -3
A9: 1020 | B9: 555 Boulevard - Rent Plus Services | C9: Each | D9: 1 | E9: 7.85 | F9: 7.85 | G9: {=SUMPRODUCT(IF($E9=$O$2,$D9*$P$2,IF($E9=$O$3,$D9*$P$3,IF($E9=$O$4,$D9*$P$4,IF($E9=$O$5,$D9*$P$5,IF($E9=$O$6,$D9*$P$6, IF($E9=$O$7,$D9*$P$7,IF($E9=$O$8,$D9*$P$8,IF($E9=$O$9,$D9*$P$9,IF($E9=$O$10,$D9*$P$10,IF($E9=$O$11,$D9*$P$11,IF($E9=$O$12,$D9*$P$12,IF($E9=$O$13,$D9*$P$13,IF($E9=$O$14,$D9*$P$14,IF($E9=$O$15,$D9*$P$15,IF($E9=$O$16,$D9*$P$16,IF($E9=$O$17,$D9*$P$17,IF($E9=$O$18,$D9*$P$18,IF($E9=$O$19,$D9*$P$19,IF($E9=$O$20,$D9*$P$20,IF($E9=$O$21,$D9*$P$21,IF($E9=$O$22,$D9*$P$22,IF($E9=$O$23,$D9*$P$23,IF($E9=$O$24,$D9*$P$24,IF($E9=$O$25,$D9*$P$25,IF($E9=$O$26,$D9*$P$26,IF($E9=$O$27,$D9*$P$27,IF($E9=$O$28,$D9*$P$28,IF($E9=$O$29,$D9*$P$29,IF($E9=$O$30,$D9*$P$30,IF($E9=$O$31,$D9*$P$31,IF($E9=$O$32,$D9*$P$32,IF($E9=$O$33,$D9*$P$33,IF($E9=$O$34,$D9*$P$34,IF($E9=$O$35,$D9*$P$35,n/a)))))))))))))))))))))))))))))))))))} -> 1 | H9: =IF($E9<0,$G9*10,0) -> 0 | N9: Reversal | O9: -31.4 | P9: -4
A10: 1020 | B10: 555 Boulevard - Rent Plus Services (past triple) | C10: Each | D10: 11 | E10: 12.8 | F10: 140.8 | G10: {=SUMPRODUCT(IF($E10=$O$2,$D10*$P$2,IF($E10=$O$3,$D10*$P$3,IF($E10=$O$4,$D10*$P$4,IF($E10=$O$5,$D10*$P$5,IF($E10=$O$6,$D10*$P$6, IF($E10=$O$7,$D10*$P$7,IF($E10=$O$8,$D10*$P$8,IF($E10=$O$9,$D10*$P$9,IF($E10=$O$10,$D10*$P$10,IF($E10=$O$11,$D10*$P$11,IF($E10=$O$12,$D10*$P$12,IF($E10=$O$13,$D10*$P$13,IF($E10=$O$14,$D10*$P$14,IF($E10=$O$15,$D10*$P$15,IF($E10=$O$16,$D10*$P$16,IF($E10=$O$17,$D10*$P$17,IF($E10=$O$18,$D10*$P$18,IF($E10=$O$19,$D10*$P$19,IF($E10=$O$20,$D10*$P$20,IF($E10=$O$21,$D10*$P$21,IF($E10=$O$22,$D10*$P$22,IF($E10=$O$23,$D10*$P$23,IF($E10=$O$24,$D10*$P$24,IF($E10=$O$25,$D10*$P$25,IF($E10=$O$26,$D10*$P$26,IF($E10=$O$27,$D10*$P$27,IF($E10=$O$28,$D10*$P$28,IF($E10=$O$29,$D10*$P$29,IF($E10=$O$30,$D10*$P$30,IF($E10=$O$31,$D10*$P$31,IF($E10=$O$32,$D10*$P$32,IF($E10=$O$33,$D10*$P$33,IF($E10=$O$34,$D10*$P$34,IF($E10=$O$35,$D10*$P$35,n/a)))))))))))))))))))))))))))))))))))} -> 11 | H10: =IF($E10<0,$G10*10,0) -> 0 | M10: Other Charges | N10: Single Charge | O10: 4.85 | P10: 1
A11: 1020 | B11: 555 Boulevard - Rent Plus Services (past double) | C11: Each | D11: 1 | E11: -7.8 | F11: -7.8 | G11: {=SUMPRODUCT(IF($E11=$O$2,$D11*$P$2,IF($E11=$O$3,$D11*$P$3,IF($E11=$O$4,$D11*$P$4,IF($E11=$O$5,$D11*$P$5,IF($E11=$O$6,$D11*$P$6, IF($E11=$O$7,$D11*$P$7,IF($E11=$O$8,$D11*$P$8,IF($E11=$O$9,$D11*$P$9,IF($E11=$O$10,$D11*$P$10,IF($E11=$O$11,$D11*$P$11,IF($E11=$O$12,$D11*$P$12,IF($E11=$O$13,$D11*$P$13,IF($E11=$O$14,$D11*$P$14,IF($E11=$O$15,$D11*$P$15,IF($E11=$O$16,$D11*$P$16,IF($E11=$O$17,$D11*$P$17,IF($E11=$O$18,$D11*$P$18,IF($E11=$O$19,$D11*$P$19,IF($E11=$O$20,$D11*$P$20,IF($E11=$O$21,$D11*$P$21,IF($E11=$O$22,$D11*$P$22,IF($E11=$O$23,$D11*$P$23,IF($E11=$O$24,$D11*$P$24,IF($E11=$O$25,$D11*$P$25,IF($E11=$O$26,$D11*$P$26,IF($E11=$O$27,$D11*$P$27,IF($E11=$O$28,$D11*$P$28,IF($E11=$O$29,$D11*$P$29,IF($E11=$O$30,$D11*$P$30,IF($E11=$O$31,$D11*$P$31,IF($E11=$O$32,$D11*$P$32,IF($E11=$O$33,$D11*$P$33,IF($E11=$O$34,$D11*$P$34,IF($E11=$O$35,$D11*$P$35,n/a)))))))))))))))))))))))))))))))))))} -> -1 | H11: =IF($E11<0,$G11*10,0) -> -10 | N11: Reversal | O11: -4.85 | P11: -1
A12: 1020 | B12: 698 Prospect - Rent Plus Services | C12: Each | D12: 119 | E12: 7.85 | F12: 934.15 | G12: {=SUMPRODUCT(IF($E12=$O$2,$D12*$P$2,IF($E12=$O$3,$D12*$P$3,IF($E12=$O$4,$D12*$P$4,IF($E12=$O$5,$D12*$P$5,IF($E12=$O$6,$D12*$P$6, IF($E12=$O$7,$D12*$P$7,IF($E12=$O$8,$D12*$P$8,IF($E12=$O$9,$D12*$P$9,IF($E12=$O$10,$D12*$P$10,IF($E12=$O$11,$D12*$P$11,IF($E12=$O$12,$D12*$P$12,IF($E12=$O$13,$D12*$P$13,IF($E12=$O$14,$D12*$P$14,IF($E12=$O$15,$D12*$P$15,IF($E12=$O$16,$D12*$P$16,IF($E12=$O$17,$D12*$P$17,IF($E12=$O$18,$D12*$P$18,IF($E12=$O$19,$D12*$P$19,IF($E12=$O$20,$D12*$P$20,IF($E12=$O$21,$D12*$P$21,IF($E12=$O$22,$D12*$P$22,IF($E12=$O$23,$D12*$P$23,IF($E12=$O$24,$D12*$P$24,IF($E12=$O$25,$D12*$P$25,IF($E12=$O$26,$D12*$P$26,IF($E12=$O$27,$D12*$P$27,IF($E12=$O$28,$D12*$P$28,IF($E12=$O$29,$D12*$P$29,IF($E12=$O$30,$D12*$P$30,IF($E12=$O$31,$D12*$P$31,IF($E12=$O$32,$D12*$P$32,IF($E12=$O$33,$D12*$P$33,IF($E12=$O$34,$D12*$P$34,IF($E12=$O$35,$D12*$P$35,n/a)))))))))))))))))))))))))))))))))))} -> 119 | H12: =IF($E12<0,$G12*10,0) -> 0 | N12: Single Charge | O12: 5.85 | P12: 1
A13: 1020 | B13: 698 Prospect - Rent Plus Services | C13: Each | D13: 1 | E13: -7.85 | F13: -7.85 | G13: {=SUMPRODUCT(IF($E13=$O$2,$D13*$P$2,IF($E13=$O$3,$D13*$P$3,IF($E13=$O$4,$D13*$P$4,IF($E13=$O$5,$D13*$P$5,IF($E13=$O$6,$D13*$P$6, IF($E13=$O$7,$D13*$P$7,IF($E13=$O$8,$D13*$P$8,IF($E13=$O$9,$D13*$P$9,IF($E13=$O$10,$D13*$P$10,IF($E13=$O$11,$D13*$P$11,IF($E13=$O$12,$D13*$P$12,IF($E13=$O$13,$D13*$P$13,IF($E13=$O$14,$D13*$P$14,IF($E13=$O$15,$D13*$P$15,IF($E13=$O$16,$D13*$P$16,IF($E13=$O$17,$D13*$P$17,IF($E13=$O$18,$D13*$P$18,IF($E13=$O$19,$D13*$P$19,IF($E13=$O$20,$D13*$P$20,IF($E13=$O$21,$D13*$P$21,IF($E13=$O$22,$D13*$P$22,IF($E13=$O$23,$D13*$P$23,IF($E13=$O$24,$D13*$P$24,IF($E13=$O$25,$D13*$P$25,IF($E13=$O$26,$D13*$P$26,IF($E13=$O$27,$D13*$P$27,IF($E13=$O$28,$D13*$P$28,IF($E13=$O$29,$D13*$P$29,IF($E13=$O$30,$D13*$P$30,IF($E13=$O$31,$D13*$P$31,IF($E13=$O$32,$D13*$P$32,IF($E13=$O$33,$D13*$P$33,IF($E13=$O$34,$D13*$P$34,IF($E13=$O$35,$D13*$P$35,n/a)))))))))))))))))))))))))))))))))))} -> -1 | H13: =IF($E13<0,$G13*10,0) -> -10 | N13: Reversal | O13: -5.85 | P13: -1
A14: 1020 | B14: Auden Upstate - Rent Plus Services | C14: Each | D14: 37 | E14: 7.85 | F14: 290.45 | G14: {=SUMPRODUCT(IF($E14=$O$2,$D14*$P$2,IF($E14=$O$3,$D14*$P$3,IF($E14=$O$4,$D14*$P$4,IF($E14=$O$5,$D14*$P$5,IF($E14=$O$6,$D14*$P$6, IF($E14=$O$7,$D14*$P$7,IF($E14=$O$8,$D14*$P$8,IF($E14=$O$9,$D14*$P$9,IF($E14=$O$10,$D14*$P$10,IF($E14=$O$11,$D14*$P$11,IF($E14=$O$12,$D14*$P$12,IF($E14=$O$13,$D14*$P$13,IF($E14=$O$14,$D14*$P$14,IF($E14=$O$15,$D14*$P$15,IF($E14=$O$16,$D14*$P$16,IF($E14=$O$17,$D14*$P$17,IF($E14=$O$18,$D14*$P$18,IF($E14=$O$19,$D14*$P$19,IF($E14=$O$20,$D14*$P$20,IF($E14=$O$21,$D14*$P$21,IF($E14=$O$22,$D14*$P$22,IF($E14=$O$23,$D14*$P$23,IF($E14=$O$24,$D14*$P$24,IF($E14=$O$25,$D14*$P$25,IF($E14=$O$26,$D14*$P$26,IF($E14=$O$27,$D14*$P$27,IF($E14=$O$28,$D14*$P$28,IF($E14=$O$29,$D14*$P$29,IF($E14=$O$30,$D14*$P$30,IF($E14=$O$31,$D14*$P$31,IF($E14=$O$32,$D14*$P$32,IF($E14=$O$33,$D14*$P$33,IF($E14=$O$34,$D14*$P$34,IF($E14=$O$35,$D14*$P$35,n/a)))))))))))))))))))))))))))))))))))} -> 37 | H14: =IF($E14<0,$G14*10,0) -> 0 | N14: Single Charge | O14: 5.95 | P14: 1
A15: 1020 | B15: Beach Club - Rent Plus Services (past) | C15: Each | D15: 68 | E15: 6.8 | F15: 462.4 | G15: {=SUMPRODUCT(IF($E15=$O$2,$D15*$P$2,IF($E15=$O$3,$D15*$P$3,IF($E15=$O$4,$D15*$P$4,IF($E15=$O$5,$D15*$P$5,IF($E15=$O$6,$D15*$P$6, IF($E15=$O$7,$D15*$P$7,IF($E15=$O$8,$D15*$P$8,IF($E15=$O$9,$D15*$P$9,IF($E15=$O$10,$D15*$P$10,IF($E15=$O$11,$D15*$P$11,IF($E15=$O$12,$D15*$P$12,IF($E15=$O$13,$D15*$P$13,IF($E15=$O$14,$D15*$P$14,IF($E15=$O$15,$D15*$P$15,IF($E15=$O$16,$D15*$P$16,IF($E15=$O$17,$D15*$P$17,IF($E15=$O$18,$D15*$P$18,IF($E15=$O$19,$D15*$P$19,IF($E15=$O$20,$D15*$P$20,IF($E15=$O$21,$D15*$P$21,IF($E15=$O$22,$D15*$P$22,IF($E15=$O$23,$D15*$P$23,IF($E15=$O$24,$D15*$P$24,IF($E15=$O$25,$D15*$P$25,IF($E15=$O$26,$D15*$P$26,IF($E15=$O$27,$D15*$P$27,IF($E15=$O$28,$D15*$P$28,IF($E15=$O$29,$D15*$P$29,IF($E15=$O$30,$D15*$P$30,IF($E15=$O$31,$D15*$P$31,IF($E15=$O$32,$D15*$P$32,IF($E15=$O$33,$D15*$P$33,IF($E15=$O$34,$D15*$P$34,IF($E15=$O$35,$D15*$P$35,n/a)))))))))))))))))))))))))))))))))))} -> 68 | H15: =IF($E15<0,$G15*10,0) -> 0 | N15: Reversal | O15: -5.95 | P15: -1
A16: 1020 | B16: Beach Club - Rent Plus Services | C16: Each | D16: 33 | E16: 7.85 | F16: 259.05 | G16: {=SUMPRODUCT(IF($E16=$O$2,$D16*$P$2,IF($E16=$O$3,$D16*$P$3,IF($E16=$O$4,$D16*$P$4,IF($E16=$O$5,$D16*$P$5,IF($E16=$O$6,$D16*$P$6, IF($E16=$O$7,$D16*$P$7,IF($E16=$O$8,$D16*$P$8,IF($E16=$O$9,$D16*$P$9,IF($E16=$O$10,$D16*$P$10,IF($E16=$O$11,$D16*$P$11,IF($E16=$O$12,$D16*$P$12,IF($E16=$O$13,$D16*$P$13,IF($E16=$O$14,$D16*$P$14,IF($E16=$O$15,$D16*$P$15,IF($E16=$O$16,$D16*$P$16,IF($E16=$O$17,$D16*$P$17,IF($E16=$O$18,$D16*$P$18,IF($E16=$O$19,$D16*$P$19,IF($E16=$O$20,$D16*$P$20,IF($E16=$O$21,$D16*$P$21,IF($E16=$O$22,$D16*$P$22,IF($E16=$O$23,$D16*$P$23,IF($E16=$O$24,$D16*$P$24,IF($E16=$O$25,$D16*$P$25,IF($E16=$O$26,$D16*$P$26,IF($E16=$O$27,$D16*$P$27,IF($E16=$O$28,$D16*$P$28,IF($E16=$O$29,$D16*$P$29,IF($E16=$O$30,$D16*$P$30,IF($E16=$O$31,$D16*$P$31,IF($E16=$O$32,$D16*$P$32,IF($E16=$O$33,$D16*$P$33,IF($E16=$O$34,$D16*$P$34,IF($E16=$O$35,$D16*$P$35,n/a)))))))))))))))))))))))))))))))))))} -> 33 | H16: =IF($E16<0,$G16*10,0) -> 0 | N16: Single Charge | O16: 6.8 | P16: 1
A17: 1020 | B17: Beach Club - Rent Plus Services (past double) | C17: Each | D17: 1 | E17: 12.8 | F17: 12.8 | G17: {=SUMPRODUCT(IF($E17=$O$2,$D17*$P$2,IF($E17=$O$3,$D17*$P$3,IF($E17=$O$4,$D17*$P$4,IF($E17=$O$5,$D17*$P$5,IF($E17=$O$6,$D17*$P$6, IF($E17=$O$7,$D17*$P$7,IF($E17=$O$8,$D17*$P$8,IF($E17=$O$9,$D17*$P$9,IF($E17=$O$10,$D17*$P$10,IF($E17=$O$11,$D17*$P$11,IF($E17=$O$12,$D17*$P$12,IF($E17=$O$13,$D17*$P$13,IF($E17=$O$14,$D17*$P$14,IF($E17=$O$15,$D17*$P$15,IF($E17=$O$16,$D17*$P$16,IF($E17=$O$17,$D17*$P$17,IF($E17=$O$18,$D17*$P$18,IF($E17=$O$19,$D17*$P$19,IF($E17=$O$20,$D17*$P$20,IF($E17=$O$21,$D17*$P$21,IF($E17=$O$22,$D17*$P$22,IF($E17=$O$23,$D17*$P$23,IF($E17=$O$24,$D17*$P$24,IF($E17=$O$25,$D17*$P$25,IF($E17=$O$26,$D17*$P$26,IF($E17=$O$27,$D17*$P$27,IF($E17=$O$28,$D17*$P$28,IF($E17=$O$29,$D17*$P$29,IF($E17=$O$30,$D17*$P$30,IF($E17=$O$31,$D17*$P$31,IF($E17=$O$32,$D17*$P$32,IF($E17=$O$33,$D17*$P$33,IF($E17=$O$34,$D17*$P$34,IF($E17=$O$35,$D17*$P$35,n/a)))))))))))))))))))))))))))))))))))} -> 1 | H17: =IF($E17<0,$G17*10,0) -> 0 | N17: Reversal | O17: -6.8 | P17: -1
A18: 1020 | B18: Beach Club - Rent Plus Services (past triple) | C18: Each | D18: 8 | E18: 14.65 | F18: 117.2 | G18: {=SUMPRODUCT(IF($E18=$O$2,$D18*$P$2,IF($E18=$O$3,$D18*$P$3,IF($E18=$O$4,$D18*$P$4,IF($E18=$O$5,$D18*$P$5,IF($E18=$O$6,$D18*$P$6, IF($E18=$O$7,$D18*$P$7,IF($E18=$O$8,$D18*$P$8,IF($E18=$O$9,$D18*$P$9,IF($E18=$O$10,$D18*$P$10,IF($E18=$O$11,$D18*$P$11,IF($E18=$O$12,$D18*$P$12,IF($E18=$O$13,$D18*$P$13,IF($E18=$O$14,$D18*$P$14,IF($E18=$O$15,$D18*$P$15,IF($E18=$O$16,$D18*$P$16,IF($E18=$O$17,$D18*$P$17,IF($E18=$O$18,$D18*$P$18,IF($E18=$O$19,$D18*$P$19,IF($E18=$O$20,$D18*$P$20,IF($E18=$O$21,$D18*$P$21,IF($E18=$O$22,$D18*$P$22,IF($E18=$O$23,$D18*$P$23,IF($E18=$O$24,$D18*$P$24,IF($E18=$O$25,$D18*$P$25,IF($E18=$O$26,$D18*$P$26,IF($E18=$O$27,$D18*$P$27,IF($E18=$O$28,$D18*$P$28,IF($E18=$O$29,$D18*$P$29,IF($E18=$O$30,$D18*$P$30,IF($E18=$O$31,$D18*$P$31,IF($E18=$O$32,$D18*$P$32,IF($E18=$O$33,$D18*$P$33,IF($E18=$O$34,$D18*$P$34,IF($E18=$O$35,$D18*$P$35,n/a)))))))))))))))))))))))))))))))))))} -> 8 | H18: =IF($E18<0,$G18*10,0) -> 0 | N18: Single Charge | O18: 6.85 | P18: 1
A19: 1020 | B19: Beach Club - Rent Plus Services | C19: Each | D19: 11 | E19: 15.7 | F19: 172.7 | G19: {=SUMPRODUCT(IF($E19=$O$2,$D19*$P$2,IF($E19=$O$3,$D19*$P$3,IF($E19=$O$4,$D19*$P$4,IF($E19=$O$5,$D19*$P$5,IF($E19=$O$6,$D19*$P$6, IF($E19=$O$7,$D19*$P$7,IF($E19=$O$8,$D19*$P$8,IF($E19=$O$9,$D19*$P$9,IF($E19=$O$10,$D19*$P$10,IF($E19=$O$11,$D19*$P$11,IF($E19=$O$12,$D19*$P$12,IF($E19=$O$13,$D19*$P$13,IF($E19=$O$14,$D19*$P$14,IF($E19=$O$15,$D19*$P$15,IF($E19=$O$16,$D19*$P$16,IF($E19=$O$17,$D19*$P$17,IF($E19=$O$18,$D19*$P$18,IF($E19=$O$19,$D19*$P$19,IF($E19=$O$20,$D19*$P$20,IF($E19=$O$21,$D19*$P$21,IF($E19=$O$22,$D19*$P$22,IF($E19=$O$23,$D19*$P$23,IF($E19=$O$24,$D19*$P$24,IF($E19=$O$25,$D19*$P$25,IF($E19=$O$26,$D19*$P$26,IF($E19=$O$27,$D19*$P$27,IF($E19=$O$28,$D19*$P$28,IF($E19=$O$29,$D19*$P$29,IF($E19=$O$30,$D19*$P$30,IF($E19=$O$31,$D19*$P$31,IF($E19=$O$32,$D19*$P$32,IF($E19=$O$33,$D19*$P$33,IF($E19=$O$34,$D19*$P$34,IF($E19=$O$35,$D19*$P$35,n/a)))))))))))))))))))))))))))))))))))} -> 22 | H19: =IF($E19<0,$G19*10,0) -> 0 | N19: Reversal | O19: -6.85 | P19: -1
A20: 1020 | B20: Beach Club - Rent Plus Services (past quad) | C20: Each | D20: 2 | E20: 20.65 | F20: 41.3 | G20: {=SUMPRODUCT(IF($E20=$O$2,$D20*$P$2,IF($E20=$O$3,$D20*$P$3,IF($E20=$O$4,$D20*$P$4,IF($E20=$O$5,$D20*$P$5,IF($E20=$O$6,$D20*$P$6, IF($E20=$O$7,$D20*$P$7,IF($E20=$O$8,$D20*$P$8,IF($E20=$O$9,$D20*$P$9,IF($E20=$O$10,$D20*$P$10,IF($E20=$O$11,$D20*$P$11,IF($E20=$O$12,$D20*$P$12,IF($E20=$O$13,$D20*$P$13,IF($E20=$O$14,$D20*$P$14,IF($E20=$O$15,$D20*$P$15,IF($E20=$O$16,$D20*$P$16,IF($E20=$O$17,$D20*$P$17,IF($E20=$O$18,$D20*$P$18,IF($E20=$O$19,$D20*$P$19,IF($E20=$O$20,$D20*$P$20,IF($E20=$O$21,$D20*$P$21,IF($E20=$O$22,$D20*$P$22,IF($E20=$O$23,$D20*$P$23,IF($E20=$O$24,$D20*$P$24,IF($E20=$O$25,$D20*$P$25,IF($E20=$O$26,$D20*$P$26,IF($E20=$O$27,$D20*$P$27,IF($E20=$O$28,$D20*$P$28,IF($E20=$O$29,$D20*$P$29,IF($E20=$O$30,$D20*$P$30,IF($E20=$O$31,$D20*$P$31,IF($E20=$O$32,$D20*$P$32,IF($E20=$O$33,$D20*$P$33,IF($E20=$O$34,$D20*$P$34,IF($E20=$O$35,$D20*$P$35,n/a)))))))))))))))))))))))))))))))))))} -> 2 | H20: =IF($E20<0,$G20*10,0) -> 0 | N20: Double Charge | O20: 7.8 | P20: 1
A21: 1020 | B21: Beach Club - Rent Plus Services | C21: Each | D21: 1 | E21: 23.55 | F21: 23.55 | G21: {=SUMPRODUCT(IF($E21=$O$2,$D21*$P$2,IF($E21=$O$3,$D21*$P$3,IF($E21=$O$4,$D21*$P$4,IF($E21=$O$5,$D21*$P$5,IF($E21=$O$6,$D21*$P$6, IF($E21=$O$7,$D21*$P$7,IF($E21=$O$8,$D21*$P$8,IF($E21=$O$9,$D21*$P$9,IF($E21=$O$10,$D21*$P$10,IF($E21=$O$11,$D21*$P$11,IF($E21=$O$12,$D21*$P$12,IF($E21=$O$13,$D21*$P$13,IF($E21=$O$14,$D21*$P$14,IF($E21=$O$15,$D21*$P$15,IF($E21=$O$16,$D21*$P$16,IF($E21=$O$17,$D21*$P$17,IF($E21=$O$18,$D21*$P$18,IF($E21=$O$19,$D21*$P$19,IF($E21=$O$20,$D21*$P$20,IF($E21=$O$21,$D21*$P$21,IF($E21=$O$22,$D21*$P$22,IF($E21=$O$23,$D21*$P$23,IF($E21=$O$24,$D21*$P$24,IF($E21=$O$25,$D21*$P$25,IF($E21=$O$26,$D21*$P$26,IF($E21=$O$27,$D21*$P$27,IF($E21=$O$28,$D21*$P$28,IF($E21=$O$29,$D21*$P$29,IF($E21=$O$30,$D21*$P$30,IF($E21=$O$31,$D21*$P$31,IF($E21=$O$32,$D21*$P$32,IF($E21=$O$33,$D21*$P$33,IF($E21=$O$34,$D21*$P$34,IF($E21=$O$35,$D21*$P$35,n/a)))))))))))))))))))))))))))))))))))} -> 3 | H21: =IF($E21<0,$G21*10,0) -> 0 | N21: Reversal | O21: -7.8 | P21: -1
A22: 1020 | B22: Beach Club - Rent Plus Services (past) | C22: Each | D22: 1 | E22: -6.8 | F22: -6.8 | G22: {=SUMPRODUCT(IF($E22=$O$2,$D22*$P$2,IF($E22=$O$3,$D22*$P$3,IF($E22=$O$4,$D22*$P$4,IF($E22=$O$5,$D22*$P$5,IF($E22=$O$6,$D22*$P$6, IF($E22=$O$7,$D22*$P$7,IF($E22=$O$8,$D22*$P$8,IF($E22=$O$9,$D22*$P$9,IF($E22=$O$10,$D22*$P$10,IF($E22=$O$11,$D22*$P$11,IF($E22=$O$12,$D22*$P$12,IF($E22=$O$13,$D22*$P$13,IF($E22=$O$14,$D22*$P$14,IF($E22=$O$15,$D22*$P$15,IF($E22=$O$16,$D22*$P$16,IF($E22=$O$17,$D22*$P$17,IF($E22=$O$18,$D22*$P$18,IF($E22=$O$19,$D22*$P$19,IF($E22=$O$20,$D22*$P$20,IF($E22=$O$21,$D22*$P$21,IF($E22=$O$22,$D22*$P$22,IF($E22=$O$23,$D22*$P$23,IF($E22=$O$24,$D22*$P$24,IF($E22=$O$25,$D22*$P$25,IF($E22=$O$26,$D22*$P$26,IF($E22=$O$27,$D22*$P$27,IF($E22=$O$28,$D22*$P$28,IF($E22=$O$29,$D22*$P$29,IF($E22=$O$30,$D22*$P$30,IF($E22=$O$31,$D22*$P$31,IF($E22=$O$32,$D22*$P$32,IF($E22=$O$33,$D22*$P$33,IF($E22=$O$34,$D22*$P$34,IF($E22=$O$35,$D22*$P$35,n/a)))))))))))))))))))))))))))))))))))} -> -1 | H22: =IF($E22<0,$G22*10,0) -> -10 | N22: Single Charge | O22: 6.95 | P22: 1
... A35: 1020 | B35: Campus Creek Townhomes - Rent Plus Services | C35: Each | D35: 11 | E35: 15.7 | F35: 172.7 | G35: {=SUMPRODUCT(IF($E35=$O$2,$D35*$P$2,IF($E35=$O$3,$D35*$P$3,IF($E35=$O$4,$D35*$P$4,IF($E35=$O$5,$D35*$P$5,IF($E35=$O$6,$D35*$P$6, IF($E35=$O$7,$D35*$P$7,IF($E35=$O$8,$D35*$P$8,IF($E35=$O$9,$D35*$P$9,IF($E35=$O$10,$D35*$P$10,IF($E35=$O$11,$D35*$P$11,IF($E35=$O$12,$D35*$P$12,IF($E35=$O$13,$D35*$P$13,IF($E35=$O$14,$D35*$P$14,IF($E35=$O$15,$D35*$P$15,IF($E35=$O$16,$D35*$P$16,IF($E35=$O$17,$D35*$P$17,IF($E35=$O$18,$D35*$P$18,IF($E35=$O$19,$D35*$P$19,IF($E35=$O$20,$D35*$P$20,IF($E35=$O$21,$D35*$P$21,IF($E35=$O$22,$D35*$P$22,IF($E35=$O$23,$D35*$P$23,IF($E35=$O$24,$D35*$P$24,IF($E35=$O$25,$D35*$P$25,IF($E35=$O$26,$D35*$P$26,IF($E35=$O$27,$D35*$P$27,IF($E35=$O$28,$D35*$P$28,IF($E35=$O$29,$D35*$P$29,IF($E35=$O$30,$D35*$P$30,IF($E35=$O$31,$D35*$P$31,IF($E35=$O$32,$D35*$P$32,IF($E35=$O$33,$D35*$P$33,IF($E35=$O$34,$D35*$P$34,IF($E35=$O$35,$D35*$P$35,n/a)))))))))))))))))))))))))))))))))))} -> 22 | H35: =IF($E35<0,$G35*10,0) -> 0 | N35: Reversal | O35: -12.85 | P35: -1
A36: 1020 | B36: Campus Creek Townhomes - Rent Plus Services | C36: Each | D36: 1 | E36: 31.4 | F36: 31.4 | G36: {=SUMPRODUCT(IF($E36=$O$2,$D36*$P$2,IF($E36=$O$3,$D36*$P$3,IF($E36=$O$4,$D36*$P$4,IF($E36=$O$5,$D36*$P$5,IF($E36=$O$6,$D36*$P$6, IF($E36=$O$7,$D36*$P$7,IF($E36=$O$8,$D36*$P$8,IF($E36=$O$9,$D36*$P$9,IF($E36=$O$10,$D36*$P$10,IF($E36=$O$11,$D36*$P$11,IF($E36=$O$12,$D36*$P$12,IF($E36=$O$13,$D36*$P$13,IF($E36=$O$14,$D36*$P$14,IF($E36=$O$15,$D36*$P$15,IF($E36=$O$16,$D36*$P$16,IF($E36=$O$17,$D36*$P$17,IF($E36=$O$18,$D36*$P$18,IF($E36=$O$19,$D36*$P$19,IF($E36=$O$20,$D36*$P$20,IF($E36=$O$21,$D36*$P$21,IF($E36=$O$22,$D36*$P$22,IF($E36=$O$23,$D36*$P$23,IF($E36=$O$24,$D36*$P$24,IF($E36=$O$25,$D36*$P$25,IF($E36=$O$26,$D36*$P$26,IF($E36=$O$27,$D36*$P$27,IF($E36=$O$28,$D36*$P$28,IF($E36=$O$29,$D36*$P$29,IF($E36=$O$30,$D36*$P$30,IF($E36=$O$31,$D36*$P$31,IF($E36=$O$32,$D36*$P$32,IF($E36=$O$33,$D36*$P$33,IF($E36=$O$34,$D36*$P$34,IF($E36=$O$35,$D36*$P$35,n/a)))))))))))))))))))))))))))))))))))} -> 4 | H36: =IF($E36<0,$G36*10,0) -> 0
A37: 1020 | B37: Castleberry Park - Rent Plus Services (past) | C37: Each | D37: 32 | E37: 6.8 | F37: 217.6 | G37: {=SUMPRODUCT(IF($E37=$O$2,$D37*$P$2,IF($E37=$O$3,$D37*$P$3,IF($E37=$O$4,$D37*$P$4,IF($E37=$O$5,$D37*$P$5,IF($E37=$O$6,$D37*$P$6, IF($E37=$O$7,$D37*$P$7,IF($E37=$O$8,$D37*$P$8,IF($E37=$O$9,$D37*$P$9,IF($E37=$O$10,$D37*$P$10,IF($E37=$O$11,$D37*$P$11,IF($E37=$O$12,$D37*$P$12,IF($E37=$O$13,$D37*$P$13,IF($E37=$O$14,$D37*$P$14,IF($E37=$O$15,$D37*$P$15,IF($E37=$O$16,$D37*$P$16,IF($E37=$O$17,$D37*$P$17,IF($E37=$O$18,$D37*$P$18,IF($E37=$O$19,$D37*$P$19,IF($E37=$O$20,$D37*$P$20,IF($E37=$O$21,$D37*$P$21,IF($E37=$O$22,$D37*$P$22,IF($E37=$O$23,$D37*$P$23,IF($E37=$O$24,$D37*$P$24,IF($E37=$O$25,$D37*$P$25,IF($E37=$O$26,$D37*$P$26,IF($E37=$O$27,$D37*$P$27,IF($E37=$O$28,$D37*$P$28,IF($E37=$O$29,$D37*$P$29,IF($E37=$O$30,$D37*$P$30,IF($E37=$O$31,$D37*$P$31,IF($E37=$O$32,$D37*$P$32,IF($E37=$O$33,$D37*$P$33,IF($E37=$O$34,$D37*$P$34,IF($E37=$O$35,$D37*$P$35,n/a)))))))))))))))))))))))))))))))))))} -> 32 | H37: =IF($E37<0,$G37*10,0) -> 0
A38: 1020 | B38: Castleberry Park - Rent Plus Services | C38: Each | D38: 4 | E38: 7.8 | F38: 31.2 | G38: {=SUMPRODUCT(IF($E38=$O$2,$D38*$P$2,IF($E38=$O$3,$D38*$P$3,IF($E38=$O$4,$D38*$P$4,IF($E38=$O$5,$D38*$P$5,IF($E38=$O$6,$D38*$P$6, IF($E38=$O$7,$D38*$P$7,IF($E38=$O$8,$D38*$P$8,IF($E38=$O$9,$D38*$P$9,IF($E38=$O$10,$D38*$P$10,IF($E38=$O$11,$D38*$P$11,IF($E38=$O$12,$D38*$P$12,IF($E38=$O$13,$D38*$P$13,IF($E38=$O$14,$D38*$P$14,IF($E38=$O$15,$D38*$P$15,IF($E38=$O$16,$D38*$P$16,IF($E38=$O$17,$D38*$P$17,IF($E38=$O$18,$D38*$P$18,IF($E38=$O$19,$D38*$P$19,IF($E38=$O$20,$D38*$P$20,IF($E38=$O$21,$D38*$P$21,IF($E38=$O$22,$D38*$P$22,IF($E38=$O$23,$D38*$P$23,IF($E38=$O$24,$D38*$P$24,IF($E38=$O$25,$D38*$P$25,IF($E38=$O$26,$D38*$P$26,IF($E38=$O$27,$D38*$P$27,IF($E38=$O$28,$D38*$P$28,IF($E38=$O$29,$D38*$P$29,IF($E38=$O$30,$D38*$P$30,IF($E38=$O$31,$D38*$P$31,IF($E38=$O$32,$D38*$P$32,IF($E38=$O$33,$D38*$P$33,IF($E38=$O$34,$D38*$P$34,IF($E38=$O$35,$D38*$P$35,n/a)))))))))))))))))))))))))))))))))))} -> 4 | H38: =IF($E38<0,$G38*10,0) -> 0
A39: 1020 | B39: Castleberry Park - Rent Plus Services (past double) | C39: Each | D39: 10 | E39: 12.8 | F39: 128 | G39: {=SUMPRODUCT(IF($E39=$O$2,$D39*$P$2,IF($E39=$O$3,$D39*$P$3,IF($E39=$O$4,$D39*$P$4,IF($E39=$O$5,$D39*$P$5,IF($E39=$O$6,$D39*$P$6, IF($E39=$O$7,$D39*$P$7,IF($E39=$O$8,$D39*$P$8,IF($E39=$O$9,$D39*$P$9,IF($E39=$O$10,$D39*$P$10,IF($E39=$O$11,$D39*$P$11,IF($E39=$O$12,$D39*$P$12,IF($E39=$O$13,$D39*$P$13,IF($E39=$O$14,$D39*$P$14,IF($E39=$O$15,$D39*$P$15,IF($E39=$O$16,$D39*$P$16,IF($E39=$O$17,$D39*$P$17,IF($E39=$O$18,$D39*$P$18,IF($E39=$O$19,$D39*$P$19,IF($E39=$O$20,$D39*$P$20,IF($E39=$O$21,$D39*$P$21,IF($E39=$O$22,$D39*$P$22,IF($E39=$O$23,$D39*$P$23,IF($E39=$O$24,$D39*$P$24,IF($E39=$O$25,$D39*$P$25,IF($E39=$O$26,$D39*$P$26,IF($E39=$O$27,$D39*$P$27,IF($E39=$O$28,$D39*$P$28,IF($E39=$O$29,$D39*$P$29,IF($E39=$O$30,$D39*$P$30,IF($E39=$O$31,$D39*$P$31,IF($E39=$O$32,$D39*$P$32,IF($E39=$O$33,$D39*$P$33,IF($E39=$O$34,$D39*$P$34,IF($E39=$O$35,$D39*$P$35,n/a)))))))))))))))))))))))))))))))))))} -> 10 | H39: =IF($E39<0,$G39*10,0) -> 0
A40: 1020 | B40: Chateau on Wells - Rent Plus Services | C40: Each | D40: 2 | E40: 7.85 | F40: 15.7 | G40: {=SUMPRODUCT(IF($E40=$O$2,$D40*$P$2,IF($E40=$O$3,$D40*$P$3,IF($E40=$O$4,$D40*$P$4,IF($E40=$O$5,$D40*$P$5,IF($E40=$O$6,$D40*$P$6, IF($E40=$O$7,$D40*$P$7,IF($E40=$O$8,$D40*$P$8,IF($E40=$O$9,$D40*$P$9,IF($E40=$O$10,$D40*$P$10,IF($E40=$O$11,$D40*$P$11,IF($E40=$O$12,$D40*$P$12,IF($E40=$O$13,$D40*$P$13,IF($E40=$O$14,$D40*$P$14,IF($E40=$O$15,$D40*$P$15,IF($E40=$O$16,$D40*$P$16,IF($E40=$O$17,$D40*$P$17,IF($E40=$O$18,$D40*$P$18,IF($E40=$O$19,$D40*$P$19,IF($E40=$O$20,$D40*$P$20,IF($E40=$O$21,$D40*$P$21,IF($E40=$O$22,$D40*$P$22,IF($E40=$O$23,$D40*$P$23,IF($E40=$O$24,$D40*$P$24,IF($E40=$O$25,$D40*$P$25,IF($E40=$O$26,$D40*$P$26,IF($E40=$O$27,$D40*$P$27,IF($E40=$O$28,$D40*$P$28,IF($E40=$O$29,$D40*$P$29,IF($E40=$O$30,$D40*$P$30,IF($E40=$O$31,$D40*$P$31,IF($E40=$O$32,$D40*$P$32,IF($E40=$O$33,$D40*$P$33,IF($E40=$O$34,$D40*$P$34,IF($E40=$O$35,$D40*$P$35,n/a)))))))))))))))))))))))))))))))))))} -> 2 | H40: =IF($E40<0,$G40*10,0) -> 0
A41: 1020 | B41: Chateau on Wells - Rent Plus Services | C41: Each | D41: 1 | E41: 15.7 | F41: 15.7 | G41: {=SUMPRODUCT(IF($E41=$O$2,$D41*$P$2,IF($E41=$O$3,$D41*$P$3,IF($E41=$O$4,$D41*$P$4,IF($E41=$O$5,$D41*$P$5,IF($E41=$O$6,$D41*$P$6, IF($E41=$O$7,$D41*$P$7,IF($E41=$O$8,$D41*$P$8,IF($E41=$O$9,$D41*$P$9,IF($E41=$O$10,$D41*$P$10,IF($E41=$O$11,$D41*$P$11,IF($E41=$O$12,$D41*$P$12,IF($E41=$O$13,$D41*$P$13,IF($E41=$O$14,$D41*$P$14,IF($E41=$O$15,$D41*$P$15,IF($E41=$O$16,$D41*$P$16,IF($E41=$O$17,$D41*$P$17,IF($E41=$O$18,$D41*$P$18,IF($E41=$O$19,$D41*$P$19,IF($E41=$O$20,$D41*$P$20,IF($E41=$O$21,$D41*$P$21,IF($E41=$O$22,$D41*$P$22,IF($E41=$O$23,$D41*$P$23,IF($E41=$O$24,$D41*$P$24,IF($E41=$O$25,$D41*$P$25,IF($E41=$O$26,$D41*$P$26,IF($E41=$O$27,$D41*$P$27,IF($E41=$O$28,$D41*$P$28,IF($E41=$O$29,$D41*$P$29,IF($E41=$O$30,$D41*$P$30,IF($E41=$O$31,$D41*$P$31,IF($E41=$O$32,$D41*$P$32,IF($E41=$O$33,$D41*$P$33,IF($E41=$O$34,$D41*$P$34,IF($E41=$O$35,$D41*$P$35,n/a)))))))))))))))))))))))))))))))))))} -> 2 | H41: =IF($E41<0,$G41*10,0) -> 0
A42: 1020 | B42: Clemson Edge - Rent Plus Services | C42: Each | D42: 232 | E42: 7.85 | F42: 1821.2 | G42: {=SUMPRODUCT(IF($E42=$O$2,$D42*$P$2,IF($E42=$O$3,$D42*$P$3,IF($E42=$O$4,$D42*$P$4,IF($E42=$O$5,$D42*$P$5,IF($E42=$O$6,$D42*$P$6, IF($E42=$O$7,$D42*$P$7,IF($E42=$O$8,$D42*$P$8,IF($E42=$O$9,$D42*$P$9,IF($E42=$O$10,$D42*$P$10,IF($E42=$O$11,$D42*$P$11,IF($E42=$O$12,$D42*$P$12,IF($E42=$O$13,$D42*$P$13,IF($E42=$O$14,$D42*$P$14,IF($E42=$O$15,$D42*$P$15,IF($E42=$O$16,$D42*$P$16,IF($E42=$O$17,$D42*$P$17,IF($E42=$O$18,$D42*$P$18,IF($E42=$O$19,$D42*$P$19,IF($E42=$O$20,$D42*$P$20,IF($E42=$O$21,$D42*$P$21,IF($E42=$O$22,$D42*$P$22,IF($E42=$O$23,$D42*$P$23,IF($E42=$O$24,$D42*$P$24,IF($E42=$O$25,$D42*$P$25,IF($E42=$O$26,$D42*$P$26,IF($E42=$O$27,$D42*$P$27,IF($E42=$O$28,$D42*$P$28,IF($E42=$O$29,$D42*$P$29,IF($E42=$O$30,$D42*$P$30,IF($E42=$O$31,$D42*$P$31,IF($E42=$O$32,$D42*$P$32,IF($E42=$O$33,$D42*$P$33,IF($E42=$O$34,$D42*$P$34,IF($E42=$O$35,$D42*$P$35,n/a)))))))))))))))))))))))))))))))))))} -> 232 | H42: =IF($E42<0,$G42*10,0) -> 0
A43: 1020 | B43: Cobalt Row - Rent Plus Services | C43: Each | D43: 575 | E43: 7.85 | F43: 4513.75 | G43: {=SUMPRODUCT(IF($E43=$O$2,$D43*$P$2,IF($E43=$O$3,$D43*$P$3,IF($E43=$O$4,$D43*$P$4,IF($E43=$O$5,$D43*$P$5,IF($E43=$O$6,$D43*$P$6, IF($E43=$O$7,$D43*$P$7,IF($E43=$O$8,$D43*$P$8,IF($E43=$O$9,$D43*$P$9,IF($E43=$O$10,$D43*$P$10,IF($E43=$O$11,$D43*$P$11,IF($E43=$O$12,$D43*$P$12,IF($E43=$O$13,$D43*$P$13,IF($E43=$O$14,$D43*$P$14,IF($E43=$O$15,$D43*$P$15,IF($E43=$O$16,$D43*$P$16,IF($E43=$O$17,$D43*$P$17,IF($E43=$O$18,$D43*$P$18,IF($E43=$O$19,$D43*$P$19,IF($E43=$O$20,$D43*$P$20,IF($E43=$O$21,$D43*$P$21,IF($E43=$O$22,$D43*$P$22,IF($E43=$O$23,$D43*$P$23,IF($E43=$O$24,$D43*$P$24,IF($E43=$O$25,$D43*$P$25,IF($E43=$O$26,$D43*$P$26,IF($E43=$O$27,$D43*$P$27,IF($E43=$O$28,$D43*$P$28,IF($E43=$O$29,$D43*$P$29,IF($E43=$O$30,$D43*$P$30,IF($E43=$O$31,$D43*$P$31,IF($E43=$O$32,$D43*$P$32,IF($E43=$O$33,$D43*$P$33,IF($E43=$O$34,$D43*$P$34,IF($E43=$O$35,$D43*$P$35,n/a)))))))))))))))))))))))))))))))))))} -> 575 | H43: =IF($E43<0,$G43*10,0) -> 0
A44: 1020 | B44: Cobalt Row - Rent Plus Services | C44: Each | D44: 4 | E44: -7.85 | F44: -31.4 | G44: {=SUMPRODUCT(IF($E44=$O$2,$D44*$P$2,IF($E44=$O$3,$D44*$P$3,IF($E44=$O$4,$D44*$P$4,IF($E44=$O$5,$D44*$P$5,IF($E44=$O$6,$D44*$P$6, IF($E44=$O$7,$D44*$P$7,IF($E44=$O$8,$D44*$P$8,IF($E44=$O$9,$D44*$P$9,IF($E44=$O$10,$D44*$P$10,IF($E44=$O$11,$D44*$P$11,IF($E44=$O$12,$D44*$P$12,IF($E44=$O$13,$D44*$P$13,IF($E44=$O$14,$D44*$P$14,IF($E44=$O$15,$D44*$P$15,IF($E44=$O$16,$D44*$P$16,IF($E44=$O$17,$D44*$P$17,IF($E44=$O$18,$D44*$P$18,IF($E44=$O$19,$D44*$P$19,IF($E44=$O$20,$D44*$P$20,IF($E44=$O$21,$D44*$P$21,IF($E44=$O$22,$D44*$P$22,IF($E44=$O$23,$D44*$P$23,IF($E44=$O$24,$D44*$P$24,IF($E44=$O$25,$D44*$P$25,IF($E44=$O$26,$D44*$P$26,IF($E44=$O$27,$D44*$P$27,IF($E44=$O$28,$D44*$P$28,IF($E44=$O$29,$D44*$P$29,IF($E44=$O$30,$D44*$P$30,IF($E44=$O$31,$D44*$P$31,IF($E44=$O$32,$D44*$P$32,IF($E44=$O$33,$D44*$P$33,IF($E44=$O$34,$D44*$P$34,IF($E44=$O$35,$D44*$P$35,n/a)))))))))))))))))))))))))))))))))))} -> -4 | H44: =IF($E44<0,$G44*10,0) -> -40
A45: 1020 | B45: College Town Apartments - Rent Plus Services | C45: Each | D45: 193 | E45: 7.85 | F45: 1515.05 | G45: {=SUMPRODUCT(IF($E45=$O$2,$D45*$P$2,IF($E45=$O$3,$D45*$P$3,IF($E45=$O$4,$D45*$P$4,IF($E45=$O$5,$D45*$P$5,IF($E45=$O$6,$D45*$P$6, IF($E45=$O$7,$D45*$P$7,IF($E45=$O$8,$D45*$P$8,IF($E45=$O$9,$D45*$P$9,IF($E45=$O$10,$D45*$P$10,IF($E45=$O$11,$D45*$P$11,IF($E45=$O$12,$D45*$P$12,IF($E45=$O$13,$D45*$P$13,IF($E45=$O$14,$D45*$P$14,IF($E45=$O$15,$D45*$P$15,IF($E45=$O$16,$D45*$P$16,IF($E45=$O$17,$D45*$P$17,IF($E45=$O$18,$D45*$P$18,IF($E45=$O$19,$D45*$P$19,IF($E45=$O$20,$D45*$P$20,IF($E45=$O$21,$D45*$P$21,IF($E45=$O$22,$D45*$P$22,IF($E45=$O$23,$D45*$P$23,IF($E45=$O$24,$D45*$P$24,IF($E45=$O$25,$D45*$P$25,IF($E45=$O$26,$D45*$P$26,IF($E45=$O$27,$D45*$P$27,IF($E45=$O$28,$D45*$P$28,IF($E45=$O$29,$D45*$P$29,IF($E45=$O$30,$D45*$P$30,IF($E45=$O$31,$D45*$P$31,IF($E45=$O$32,$D45*$P$32,IF($E45=$O$33,$D45*$P$33,IF($E45=$O$34,$D45*$P$34,IF($E45=$O$35,$D45*$P$35,n/a)))))))))))))))))))))))))))))))))))} -> 193 | H45: =IF($E45<0,$G45*10,0) -> 0
A46: 1020 | B46: College Town Apartments - Rent Plus Services | C46: Each | D46: 3 | E46: 15.7 | F46: 47.1 | G46: {=SUMPRODUCT(IF($E46=$O$2,$D46*$P$2,IF($E46=$O$3,$D46*$P$3,IF($E46=$O$4,$D46*$P$4,IF($E46=$O$5,$D46*$P$5,IF($E46=$O$6,$D46*$P$6, IF($E46=$O$7,$D46*$P$7,IF($E46=$O$8,$D46*$P$8,IF($E46=$O$9,$D46*$P$9,IF($E46=$O$10,$D46*$P$10,IF($E46=$O$11,$D46*$P$11,IF($E46=$O$12,$D46*$P$12,IF($E46=$O$13,$D46*$P$13,IF($E46=$O$14,$D46*$P$14,IF($E46=$O$15,$D46*$P$15,IF($E46=$O$16,$D46*$P$16,IF($E46=$O$17,$D46*$P$17,IF($E46=$O$18,$D46*$P$18,IF($E46=$O$19,$D46*$P$19,IF($E46=$O$20,$D46*$P$20,IF($E46=$O$21,$D46*$P$21,IF($E46=$O$22,$D46*$P$22,IF($E46=$O$23,$D46*$P$23,IF($E46=$O$24,$D46*$P$24,IF($E46=$O$25,$D46*$P$25,IF($E46=$O$26,$D46*$P$26,IF($E46=$O$27,$D46*$P$27,IF($E46=$O$28,$D46*$P$28,IF($E46=$O$29,$D46*$P$29,IF($E46=$O$30,$D46*$P$30,IF($E46=$O$31,$D46*$P$31,IF($E46=$O$32,$D46*$P$32,IF($E46=$O$33,$D46*$P$33,IF($E46=$O$34,$D46*$P$34,IF($E46=$O$35,$D46*$P$35,n/a)))))))))))))))))))))))))))))))))))} -> 6 | H46: =IF($E46<0,$G46*10,0) -> 0
A47: 1020 | B47: College Town Apartments - Rent Plus Services | C47: Each | D47: 1 | E47: 23.55 | F47: 23.55 | G47: {=SUMPRODUCT(IF($E47=$O$2,$D47*$P$2,IF($E47=$O$3,$D47*$P$3,IF($E47=$O$4,$D47*$P$4,IF($E47=$O$5,$D47*$P$5,IF($E47=$O$6,$D47*$P$6, IF($E47=$O$7,$D47*$P$7,IF($E47=$O$8,$D47*$P$8,IF($E47=$O$9,$D47*$P$9,IF($E47=$O$10,$D47*$P$10,IF($E47=$O$11,$D47*$P$11,IF($E47=$O$12,$D47*$P$12,IF($E47=$O$13,$D47*$P$13,IF($E47=$O$14,$D47*$P$14,IF($E47=$O$15,$D47*$P$15,IF($E47=$O$16,$D47*$P$16,IF($E47=$O$17,$D47*$P$17,IF($E47=$O$18,$D47*$P$18,IF($E47=$O$19,$D47*$P$19,IF($E47=$O$20,$D47*$P$20,IF($E47=$O$21,$D47*$P$21,IF($E47=$O$22,$D47*$P$22,IF($E47=$O$23,$D47*$P$23,IF($E47=$O$24,$D47*$P$24,IF($E47=$O$25,$D47*$P$25,IF($E47=$O$26,$D47*$P$26,IF($E47=$O$27,$D47*$P$27,IF($E47=$O$28,$D47*$P$28,IF($E47=$O$29,$D47*$P$29,IF($E47=$O$30,$D47*$P$30,IF($E47=$O$31,$D47*$P$31,IF($E47=$O$32,$D47*$P$32,IF($E47=$O$33,$D47*$P$33,IF($E47=$O$34,$D47*$P$34,IF($E47=$O$35,$D47*$P$35,n/a)))))))))))))))))))))))))))))))))))} -> 3 | H47: =IF($E47<0,$G47*10,0) -> 0
... A162: 1020 | B162: Villas on Rio - Rent Plus Services | C162: Each | D162: 1 | E162: -7.85 | F162: -7.85 | G162: {=SUMPRODUCT(IF($E162=$O$2,$D162*$P$2,IF($E162=$O$3,$D162*$P$3,IF($E162=$O$4,$D162*$P$4,IF($E162=$O$5,$D162*$P$5,IF($E162=$O$6,$D162*$P$6, IF($E162=$O$7,$D162*$P$7,IF($E162=$O$8,$D162*$P$8,IF($E162=$O$9,$D162*$P$9,IF($E162=$O$10,$D162*$P$10,IF($E162=$O$11,$D162*$P$11,IF($E162=$O$12,$D162*$P$12,IF($E162=$O$13,$D162*$P$13,IF($E162=$O$14,$D162*$P$14,IF($E162=$O$15,$D162*$P$15,IF($E162=$O$16,$D162*$P$16,IF($E162=$O$17,$D162*$P$17,IF($E162=$O$18,$D162*$P$18,IF($E162=$O$19,$D162*$P$19,IF($E162=$O$20,$D162*$P$20,IF($E162=$O$21,$D162*$P$21,IF($E162=$O$22,$D162*$P$22,IF($E162=$O$23,$D162*$P$23,IF($E162=$O$24,$D162*$P$24,IF($E162=$O$25,$D162*$P$25,IF($E162=$O$26,$D162*$P$26,IF($E162=$O$27,$D162*$P$27,IF($E162=$O$28,$D162*$P$28,IF($E162=$O$29,$D162*$P$29,IF($E162=$O$30,$D162*$P$30,IF($E162=$O$31,$D162*$P$31,IF($E162=$O$32,$D162*$P$32,IF($E162=$O$33,$D162*$P$33,IF($E162=$O$34,$D162*$P$34,IF($E162=$O$35,$D162*$P$35,n/a)))))))))))))))))))))))))))))))))))} -> -1 | H162: =IF($E162<0,$G162*10,0) -> -10
E163: Subtotal | F163: 109790.25 | H163: =IF($E163<0,$G163*10,0) -> 0
E164: Sales Tax | F164: 0 | H164: =IF($E164<0,$G164*10,0) -> 0
E165: Total | F165: 109790.25 | H165: =IF($E165<0,$G165*10,0) -> 0
H179: =IF($E179<0,$G179*10,0) -> 0
...

Sheet Sheet1
A1: PROPERTY | D1: DESCRIPTION | E1: UNIT PRICE
A2: 48 West - Rent Plus Services | D2: 48 West - Rent Plus Services | E2: 7.85
A3: 555 Boulevard - Rent Plus Services | D3: 555 Boulevard - Rent Plus Services (past) | E3: 6.8
A4: 698 Prospect - Rent Plus Services | D4: 555 Boulevard - Rent Plus Services (past double) | E4: 7.8
A5: Auden Upstate - Rent Plus Services | D5: 555 Boulevard - Rent Plus Services | E5: 7.85
A6: Beach Club - Rent Plus Services | D6: 555 Boulevard - Rent Plus Services (past triple) | E6: 12.8
A7: Bixby Kennesaw - Rent Plus Services | D7: 698 Prospect - Rent Plus Services | E7: 7.85
A8: Brooks at Stillwater - Rent Plus Services | D8: Auden Upstate - Rent Plus Services | E8: 7.85
A9: Campus Creek Cottages - Rent Plus Services | D9: Beach Club - Rent Plus Services (past) | E9: 6.8
A10: Campus Creek Townhomes - Rent Plus Services | D10: Beach Club - Rent Plus Services | E10: 7.85
A11: Castleberry Park - Rent Plus Services | D11: Beach Club - Rent Plus Services (past double) | E11: 12.8
A12: Chateau on Wells - Rent Plus Services | D12: Beach Club - Rent Plus Services (past triple) | E12: 14.65
A13: Clemson Edge - Rent Plus Services | D13: Beach Club - Rent Plus Services (past quad) | E13: 20.65
... A65: Villas on Rio - Rent Plus Services | D65: The Finmore at 241 - Rent Plus Services | E65: 7.85
D66: The Gates - Rent Plus Services | E66: 7.85
D67: The Highlands - Rent Plus Services | E67: 7.85
D68: The Hive - Rent Plus Services | E68: 7.85
D69: The Landing Apartments - Rent Plus Services | E69: 7.85
D70: The Nine at Memphis - Rent Plus Services | E70: 7.85
D71: The Printing House - Rent Plus Services | E71: 7.85
D72: The Ranch - Rent Plus Services | E72: 7.85
D73: The Republic - Rent Plus Services | E73: 7.85
D74: The Ridge - Rent Plus Services | E74: 7.85
D75: The Summit at Coates Run - Rent Plus Services | E75: 7.85
D76: The Timbers - Rent Plus Services | E76: 7.85
D77: The Tower - Rent Plus Services | E77: 7.85
... D91: Villas on Rio - Rent Plus Services | E91: 7.85
